<?xml version="1.0" ?>
<testsuite errors="1" failures="0" name="TestParser-20181126213839" tests="3" time="0.000">
	<testcase classname="TestParser" name="test_data_loaded" time="0.000"/>
	<testcase classname="TestParser" name="test_data_no_expected" time="0.000"/>
	<testcase classname="TestParser" name="test_num_records" time="0.000">
		<error message="Incorrect number of records" type="AssertionError">
<![CDATA[Traceback (most recent call last):
  File "test.py", line 32, in test_num_records
    self.assertEqual(len(data),129, "Incorrect number of records")
AssertionError: Incorrect number of records
]]>		</error>
	</testcase>
	<system-out>
<![CDATA[]]>	</system-out>
	<system-err>
<![CDATA[]]>	</system-err>
</testsuite>
